
# >>>>>>>>>>>>>>>>>>>>>> ERROR REPORT <<<<<<<<<<<<<<<<<<<<<<

    Traceback (most recent call last):
      File "/groups/itay_mayrose/galtoledano/miniconda3/lib/python3.11/site-packages/conda/exception_handler.py", line 16, in __call__
        return func(*args, **kwargs)
               ^^^^^^^^^^^^^^^^^^^^^
      File "/groups/itay_mayrose/galtoledano/miniconda3/lib/python3.11/site-packages/conda/cli/main.py", line 84, in main_subshell
        exit_code = do_call(args, p)
                    ^^^^^^^^^^^^^^^^
      File "/groups/itay_mayrose/galtoledano/miniconda3/lib/python3.11/site-packages/conda/cli/conda_argparse.py", line 126, in do_call
        return getattr(module, func_name)(args, parser)
               ^^^^^^^^^^^^^^^^^^^^^^^^^^^^^^^^^^^^^^^^
      File "/groups/itay_mayrose/galtoledano/miniconda3/lib/python3.11/site-packages/conda/cli/main_info.py", line 354, in execute
        print_envs_list(info_dict["envs"], not context.json)
      File "/groups/itay_mayrose/galtoledano/miniconda3/lib/python3.11/site-packages/conda/cli/common.py", line 242, in print_envs_list
        disp_env(prefix)
      File "/groups/itay_mayrose/galtoledano/miniconda3/lib/python3.11/site-packages/conda/cli/common.py", line 239, in disp_env
        print(fmt % (name, active, prefix))
    BrokenPipeError: [Errno 32] Broken pipe

`$ /groups/itay_mayrose/galtoledano/miniconda3/bin/conda info --envs`


An unexpected error has occurred. Conda has prepared the above report.


# >>>>>>>>>>>>>>>>>>>>>> ERROR REPORT <<<<<<<<<<<<<<<<<<<<<<

    Traceback (most recent call last):
      File "/groups/itay_mayrose/galtoledano/miniconda3/lib/python3.11/site-packages/conda/exception_handler.py", line 16, in __call__
        return func(*args, **kwargs)
               ^^^^^^^^^^^^^^^^^^^^^
      File "/groups/itay_mayrose/galtoledano/miniconda3/lib/python3.11/site-packages/conda/cli/main.py", line 84, in main_subshell
        exit_code = do_call(args, p)
                    ^^^^^^^^^^^^^^^^
      File "/groups/itay_mayrose/galtoledano/miniconda3/lib/python3.11/site-packages/conda/cli/conda_argparse.py", line 126, in do_call
        return getattr(module, func_name)(args, parser)
               ^^^^^^^^^^^^^^^^^^^^^^^^^^^^^^^^^^^^^^^^
      File "/groups/itay_mayrose/galtoledano/miniconda3/lib/python3.11/site-packages/conda/cli/main_info.py", line 354, in execute
        print_envs_list(info_dict["envs"], not context.json)
      File "/groups/itay_mayrose/galtoledano/miniconda3/lib/python3.11/site-packages/conda/cli/common.py", line 242, in print_envs_list
        disp_env(prefix)
      File "/groups/itay_mayrose/galtoledano/miniconda3/lib/python3.11/site-packages/conda/cli/common.py", line 239, in disp_env
        print(fmt % (name, active, prefix))
    BrokenPipeError: [Errno 32] Broken pipe

`$ /groups/itay_mayrose/galtoledano/miniconda3/bin/conda info --envs`


An unexpected error has occurred. Conda has prepared the above report.


# >>>>>>>>>>>>>>>>>>>>>> ERROR REPORT <<<<<<<<<<<<<<<<<<<<<<

    Traceback (most recent call last):
      File "/groups/itay_mayrose/galtoledano/miniconda3/lib/python3.11/site-packages/conda/exception_handler.py", line 16, in __call__
        return func(*args, **kwargs)
               ^^^^^^^^^^^^^^^^^^^^^
      File "/groups/itay_mayrose/galtoledano/miniconda3/lib/python3.11/site-packages/conda/cli/main.py", line 84, in main_subshell
        exit_code = do_call(args, p)
                    ^^^^^^^^^^^^^^^^
      File "/groups/itay_mayrose/galtoledano/miniconda3/lib/python3.11/site-packages/conda/cli/conda_argparse.py", line 126, in do_call
        return getattr(module, func_name)(args, parser)
               ^^^^^^^^^^^^^^^^^^^^^^^^^^^^^^^^^^^^^^^^
      File "/groups/itay_mayrose/galtoledano/miniconda3/lib/python3.11/site-packages/conda/cli/main_info.py", line 354, in execute
        print_envs_list(info_dict["envs"], not context.json)
      File "/groups/itay_mayrose/galtoledano/miniconda3/lib/python3.11/site-packages/conda/cli/common.py", line 242, in print_envs_list
        disp_env(prefix)
      File "/groups/itay_mayrose/galtoledano/miniconda3/lib/python3.11/site-packages/conda/cli/common.py", line 239, in disp_env
        print(fmt % (name, active, prefix))
    BrokenPipeError: [Errno 32] Broken pipe

`$ /groups/itay_mayrose/galtoledano/miniconda3/bin/conda info --envs`


An unexpected error has occurred. Conda has prepared the above report.


# >>>>>>>>>>>>>>>>>>>>>> ERROR REPORT <<<<<<<<<<<<<<<<<<<<<<

    Traceback (most recent call last):
      File "/groups/itay_mayrose/galtoledano/miniconda3/lib/python3.11/site-packages/conda/exception_handler.py", line 16, in __call__
        return func(*args, **kwargs)
               ^^^^^^^^^^^^^^^^^^^^^
      File "/groups/itay_mayrose/galtoledano/miniconda3/lib/python3.11/site-packages/conda/cli/main.py", line 84, in main_subshell
        exit_code = do_call(args, p)
                    ^^^^^^^^^^^^^^^^
      File "/groups/itay_mayrose/galtoledano/miniconda3/lib/python3.11/site-packages/conda/cli/conda_argparse.py", line 126, in do_call
        return getattr(module, func_name)(args, parser)
               ^^^^^^^^^^^^^^^^^^^^^^^^^^^^^^^^^^^^^^^^
      File "/groups/itay_mayrose/galtoledano/miniconda3/lib/python3.11/site-packages/conda/cli/main_info.py", line 354, in execute
        print_envs_list(info_dict["envs"], not context.json)
      File "/groups/itay_mayrose/galtoledano/miniconda3/lib/python3.11/site-packages/conda/cli/common.py", line 242, in print_envs_list
        disp_env(prefix)
      File "/groups/itay_mayrose/galtoledano/miniconda3/lib/python3.11/site-packages/conda/cli/common.py", line 239, in disp_env
        print(fmt % (name, active, prefix))
    BrokenPipeError: [Errno 32] Broken pipe

`$ /groups/itay_mayrose/galtoledano/miniconda3/bin/conda info --envs`


An unexpected error has occurred. Conda has prepared the above report.


# >>>>>>>>>>>>>>>>>>>>>> ERROR REPORT <<<<<<<<<<<<<<<<<<<<<<

    Traceback (most recent call last):
      File "/groups/itay_mayrose/galtoledano/miniconda3/lib/python3.11/site-packages/conda/exception_handler.py", line 16, in __call__
        return func(*args, **kwargs)
               ^^^^^^^^^^^^^^^^^^^^^
      File "/groups/itay_mayrose/galtoledano/miniconda3/lib/python3.11/site-packages/conda/cli/main.py", line 84, in main_subshell
        exit_code = do_call(args, p)
                    ^^^^^^^^^^^^^^^^
      File "/groups/itay_mayrose/galtoledano/miniconda3/lib/python3.11/site-packages/conda/cli/conda_argparse.py", line 126, in do_call
        return getattr(module, func_name)(args, parser)
               ^^^^^^^^^^^^^^^^^^^^^^^^^^^^^^^^^^^^^^^^
      File "/groups/itay_mayrose/galtoledano/miniconda3/lib/python3.11/site-packages/conda/cli/main_info.py", line 354, in execute
        print_envs_list(info_dict["envs"], not context.json)
      File "/groups/itay_mayrose/galtoledano/miniconda3/lib/python3.11/site-packages/conda/cli/common.py", line 242, in print_envs_list
        disp_env(prefix)
      File "/groups/itay_mayrose/galtoledano/miniconda3/lib/python3.11/site-packages/conda/cli/common.py", line 239, in disp_env
        print(fmt % (name, active, prefix))
    BrokenPipeError: [Errno 32] Broken pipe

`$ /groups/itay_mayrose/galtoledano/miniconda3/bin/conda info --envs`


An unexpected error has occurred. Conda has prepared the above report.


# >>>>>>>>>>>>>>>>>>>>>> ERROR REPORT <<<<<<<<<<<<<<<<<<<<<<

    Traceback (most recent call last):
      File "/groups/itay_mayrose/galtoledano/miniconda3/lib/python3.11/site-packages/conda/exception_handler.py", line 16, in __call__
        return func(*args, **kwargs)
               ^^^^^^^^^^^^^^^^^^^^^
      File "/groups/itay_mayrose/galtoledano/miniconda3/lib/python3.11/site-packages/conda/cli/main.py", line 84, in main_subshell
        exit_code = do_call(args, p)
                    ^^^^^^^^^^^^^^^^
      File "/groups/itay_mayrose/galtoledano/miniconda3/lib/python3.11/site-packages/conda/cli/conda_argparse.py", line 126, in do_call
        return getattr(module, func_name)(args, parser)
               ^^^^^^^^^^^^^^^^^^^^^^^^^^^^^^^^^^^^^^^^
      File "/groups/itay_mayrose/galtoledano/miniconda3/lib/python3.11/site-packages/conda/cli/main_info.py", line 354, in execute
        print_envs_list(info_dict["envs"], not context.json)
      File "/groups/itay_mayrose/galtoledano/miniconda3/lib/python3.11/site-packages/conda/cli/common.py", line 242, in print_envs_list
        disp_env(prefix)
      File "/groups/itay_mayrose/galtoledano/miniconda3/lib/python3.11/site-packages/conda/cli/common.py", line 239, in disp_env
        print(fmt % (name, active, prefix))
    BrokenPipeError: [Errno 32] Broken pipe

`$ /groups/itay_mayrose/galtoledano/miniconda3/bin/conda info --envs`


An unexpected error has occurred. Conda has prepared the above report.

warning  libmamba Invalid package cache, file '/groups/itay_mayrose/galtoledano/miniconda3/pkgs/python-3.10.12-hd12c33a_0_cpython/lib/python3.10/tokenize.py' has incorrect size

SafetyError: The package for python located at /groups/itay_mayrose/galtoledano/miniconda3/pkgs/python-3.10.12-hd12c33a_0_cpython
appears to be corrupted. The path 'lib/python3.10/tokenize.py'
has an incorrect size.
  reported size: 25921 bytes
  actual size: 25916 bytes



# >>>>>>>>>>>>>>>>>>>>>> ERROR REPORT <<<<<<<<<<<<<<<<<<<<<<

    Traceback (most recent call last):
      File "/groups/itay_mayrose/galtoledano/miniconda3/lib/python3.11/site-packages/conda/exception_handler.py", line 16, in __call__
        return func(*args, **kwargs)
               ^^^^^^^^^^^^^^^^^^^^^
      File "/groups/itay_mayrose/galtoledano/miniconda3/lib/python3.11/site-packages/conda/cli/main.py", line 84, in main_subshell
        exit_code = do_call(args, p)
                    ^^^^^^^^^^^^^^^^
      File "/groups/itay_mayrose/galtoledano/miniconda3/lib/python3.11/site-packages/conda/cli/conda_argparse.py", line 126, in do_call
        return getattr(module, func_name)(args, parser)
               ^^^^^^^^^^^^^^^^^^^^^^^^^^^^^^^^^^^^^^^^
      File "/groups/itay_mayrose/galtoledano/miniconda3/lib/python3.11/site-packages/conda/cli/main_info.py", line 354, in execute
        print_envs_list(info_dict["envs"], not context.json)
      File "/groups/itay_mayrose/galtoledano/miniconda3/lib/python3.11/site-packages/conda/cli/common.py", line 242, in print_envs_list
        disp_env(prefix)
      File "/groups/itay_mayrose/galtoledano/miniconda3/lib/python3.11/site-packages/conda/cli/common.py", line 239, in disp_env
        print(fmt % (name, active, prefix))
    BrokenPipeError: [Errno 32] Broken pipe

`$ /groups/itay_mayrose/galtoledano/miniconda3/bin/conda info --envs`


An unexpected error has occurred. Conda has prepared the above report.


# >>>>>>>>>>>>>>>>>>>>>> ERROR REPORT <<<<<<<<<<<<<<<<<<<<<<

    Traceback (most recent call last):
      File "/groups/itay_mayrose/galtoledano/miniconda3/lib/python3.11/site-packages/conda/exception_handler.py", line 16, in __call__
        return func(*args, **kwargs)
               ^^^^^^^^^^^^^^^^^^^^^
      File "/groups/itay_mayrose/galtoledano/miniconda3/lib/python3.11/site-packages/conda/cli/main.py", line 84, in main_subshell
        exit_code = do_call(args, p)
                    ^^^^^^^^^^^^^^^^
      File "/groups/itay_mayrose/galtoledano/miniconda3/lib/python3.11/site-packages/conda/cli/conda_argparse.py", line 126, in do_call
        return getattr(module, func_name)(args, parser)
               ^^^^^^^^^^^^^^^^^^^^^^^^^^^^^^^^^^^^^^^^
      File "/groups/itay_mayrose/galtoledano/miniconda3/lib/python3.11/site-packages/conda/cli/main_info.py", line 354, in execute
        print_envs_list(info_dict["envs"], not context.json)
      File "/groups/itay_mayrose/galtoledano/miniconda3/lib/python3.11/site-packages/conda/cli/common.py", line 242, in print_envs_list
        disp_env(prefix)
      File "/groups/itay_mayrose/galtoledano/miniconda3/lib/python3.11/site-packages/conda/cli/common.py", line 239, in disp_env
        print(fmt % (name, active, prefix))
    BrokenPipeError: [Errno 32] Broken pipe

`$ /groups/itay_mayrose/galtoledano/miniconda3/bin/conda info --envs`


An unexpected error has occurred. Conda has prepared the above report.


# >>>>>>>>>>>>>>>>>>>>>> ERROR REPORT <<<<<<<<<<<<<<<<<<<<<<

    Traceback (most recent call last):
      File "/groups/itay_mayrose/galtoledano/miniconda3/lib/python3.11/site-packages/conda/exception_handler.py", line 16, in __call__
        return func(*args, **kwargs)
               ^^^^^^^^^^^^^^^^^^^^^
      File "/groups/itay_mayrose/galtoledano/miniconda3/lib/python3.11/site-packages/conda/cli/main.py", line 84, in main_subshell
        exit_code = do_call(args, p)
                    ^^^^^^^^^^^^^^^^
      File "/groups/itay_mayrose/galtoledano/miniconda3/lib/python3.11/site-packages/conda/cli/conda_argparse.py", line 126, in do_call
        return getattr(module, func_name)(args, parser)
               ^^^^^^^^^^^^^^^^^^^^^^^^^^^^^^^^^^^^^^^^
      File "/groups/itay_mayrose/galtoledano/miniconda3/lib/python3.11/site-packages/conda/cli/main_info.py", line 354, in execute
        print_envs_list(info_dict["envs"], not context.json)
      File "/groups/itay_mayrose/galtoledano/miniconda3/lib/python3.11/site-packages/conda/cli/common.py", line 242, in print_envs_list
        disp_env(prefix)
      File "/groups/itay_mayrose/galtoledano/miniconda3/lib/python3.11/site-packages/conda/cli/common.py", line 239, in disp_env
        print(fmt % (name, active, prefix))
    BrokenPipeError: [Errno 32] Broken pipe

`$ /groups/itay_mayrose/galtoledano/miniconda3/bin/conda info --envs`


An unexpected error has occurred. Conda has prepared the above report.


# >>>>>>>>>>>>>>>>>>>>>> ERROR REPORT <<<<<<<<<<<<<<<<<<<<<<

    Traceback (most recent call last):
      File "/groups/itay_mayrose/galtoledano/miniconda3/lib/python3.11/site-packages/conda/exception_handler.py", line 16, in __call__
        return func(*args, **kwargs)
               ^^^^^^^^^^^^^^^^^^^^^
      File "/groups/itay_mayrose/galtoledano/miniconda3/lib/python3.11/site-packages/conda/cli/main.py", line 84, in main_subshell
        exit_code = do_call(args, p)
                    ^^^^^^^^^^^^^^^^
      File "/groups/itay_mayrose/galtoledano/miniconda3/lib/python3.11/site-packages/conda/cli/conda_argparse.py", line 126, in do_call
        return getattr(module, func_name)(args, parser)
               ^^^^^^^^^^^^^^^^^^^^^^^^^^^^^^^^^^^^^^^^
      File "/groups/itay_mayrose/galtoledano/miniconda3/lib/python3.11/site-packages/conda/cli/main_info.py", line 354, in execute
        print_envs_list(info_dict["envs"], not context.json)
      File "/groups/itay_mayrose/galtoledano/miniconda3/lib/python3.11/site-packages/conda/cli/common.py", line 242, in print_envs_list
        disp_env(prefix)
      File "/groups/itay_mayrose/galtoledano/miniconda3/lib/python3.11/site-packages/conda/cli/common.py", line 239, in disp_env
        print(fmt % (name, active, prefix))
    BrokenPipeError: [Errno 32] Broken pipe

`$ /groups/itay_mayrose/galtoledano/miniconda3/bin/conda info --envs`


An unexpected error has occurred. Conda has prepared the above report.

warning  libmamba Problem type not implemented SOLVER_RULE_STRICT_REPO_PRIORITY
warning  libmamba Problem type not implemented SOLVER_RULE_STRICT_REPO_PRIORITY
warning  libmamba Problem type not implemented SOLVER_RULE_STRICT_REPO_PRIORITY
warning  libmamba Problem type not implemented SOLVER_RULE_STRICT_REPO_PRIORITY
warning  libmamba Problem type not implemented SOLVER_RULE_STRICT_REPO_PRIORITY
warning  libmamba Problem type not implemented SOLVER_RULE_STRICT_REPO_PRIORITY
warning  libmamba Problem type not implemented SOLVER_RULE_STRICT_REPO_PRIORITY
warning  libmamba Problem type not implemented SOLVER_RULE_STRICT_REPO_PRIORITY
warning  libmamba Problem type not implemented SOLVER_RULE_STRICT_REPO_PRIORITY
warning  libmamba Problem type not implemented SOLVER_RULE_STRICT_REPO_PRIORITY
warning  libmamba Problem type not implemented SOLVER_RULE_STRICT_REPO_PRIORITY
warning  libmamba Problem type not implemented SOLVER_RULE_STRICT_REPO_PRIORITY
warning  libmamba Problem type not implemented SOLVER_RULE_STRICT_REPO_PRIORITY
warning  libmamba Problem type not implemented SOLVER_RULE_STRICT_REPO_PRIORITY
warning  libmamba Problem type not implemented SOLVER_RULE_STRICT_REPO_PRIORITY
warning  libmamba Problem type not implemented SOLVER_RULE_STRICT_REPO_PRIORITY
warning  libmamba Problem type not implemented SOLVER_RULE_STRICT_REPO_PRIORITY
warning  libmamba Problem type not implemented SOLVER_RULE_STRICT_REPO_PRIORITY
warning  libmamba Problem type not implemented SOLVER_RULE_STRICT_REPO_PRIORITY
warning  libmamba Problem type not implemented SOLVER_RULE_STRICT_REPO_PRIORITY
warning  libmamba Problem type not implemented SOLVER_RULE_STRICT_REPO_PRIORITY
warning  libmamba Problem type not implemented SOLVER_RULE_STRICT_REPO_PRIORITY
warning  libmamba Problem type not implemented SOLVER_RULE_STRICT_REPO_PRIORITY
warning  libmamba Problem type not implemented SOLVER_RULE_STRICT_REPO_PRIORITY
warning  libmamba Problem type not implemented SOLVER_RULE_STRICT_REPO_PRIORITY
warning  libmamba Problem type not implemented SOLVER_RULE_STRICT_REPO_PRIORITY
warning  libmamba Problem type not implemented SOLVER_RULE_STRICT_REPO_PRIORITY
warning  libmamba Problem type not implemented SOLVER_RULE_STRICT_REPO_PRIORITY
warning  libmamba Problem type not implemented SOLVER_RULE_STRICT_REPO_PRIORITY
warning  libmamba Problem type not implemented SOLVER_RULE_STRICT_REPO_PRIORITY
warning  libmamba Problem type not implemented SOLVER_RULE_STRICT_REPO_PRIORITY
warning  libmamba Problem type not implemented SOLVER_RULE_STRICT_REPO_PRIORITY
warning  libmamba Problem type not implemented SOLVER_RULE_STRICT_REPO_PRIORITY
warning  libmamba Problem type not implemented SOLVER_RULE_STRICT_REPO_PRIORITY
warning  libmamba Problem type not implemented SOLVER_RULE_STRICT_REPO_PRIORITY
warning  libmamba Problem type not implemented SOLVER_RULE_STRICT_REPO_PRIORITY
warning  libmamba Problem type not implemented SOLVER_RULE_STRICT_REPO_PRIORITY
warning  libmamba Problem type not implemented SOLVER_RULE_STRICT_REPO_PRIORITY
warning  libmamba Problem type not implemented SOLVER_RULE_STRICT_REPO_PRIORITY
warning  libmamba Problem type not implemented SOLVER_RULE_STRICT_REPO_PRIORITY
warning  libmamba Problem type not implemented SOLVER_RULE_STRICT_REPO_PRIORITY
warning  libmamba Problem type not implemented SOLVER_RULE_STRICT_REPO_PRIORITY
warning  libmamba Problem type not implemented SOLVER_RULE_STRICT_REPO_PRIORITY
warning  libmamba Problem type not implemented SOLVER_RULE_STRICT_REPO_PRIORITY

# >>>>>>>>>>>>>>>>>>>>>> ERROR REPORT <<<<<<<<<<<<<<<<<<<<<<

    Traceback (most recent call last):
      File "/groups/itay_mayrose/galtoledano/miniconda3/lib/python3.11/site-packages/conda/exception_handler.py", line 16, in __call__
        return func(*args, **kwargs)
               ^^^^^^^^^^^^^^^^^^^^^
      File "/groups/itay_mayrose/galtoledano/miniconda3/lib/python3.11/site-packages/conda/cli/main.py", line 84, in main_subshell
        exit_code = do_call(args, p)
                    ^^^^^^^^^^^^^^^^
      File "/groups/itay_mayrose/galtoledano/miniconda3/lib/python3.11/site-packages/conda/cli/conda_argparse.py", line 126, in do_call
        return getattr(module, func_name)(args, parser)
               ^^^^^^^^^^^^^^^^^^^^^^^^^^^^^^^^^^^^^^^^
      File "/groups/itay_mayrose/galtoledano/miniconda3/lib/python3.11/site-packages/conda/cli/main_info.py", line 354, in execute
        print_envs_list(info_dict["envs"], not context.json)
      File "/groups/itay_mayrose/galtoledano/miniconda3/lib/python3.11/site-packages/conda/cli/common.py", line 242, in print_envs_list
        disp_env(prefix)
      File "/groups/itay_mayrose/galtoledano/miniconda3/lib/python3.11/site-packages/conda/cli/common.py", line 239, in disp_env
        print(fmt % (name, active, prefix))
    BrokenPipeError: [Errno 32] Broken pipe

`$ /groups/itay_mayrose/galtoledano/miniconda3/bin/conda info --envs`


An unexpected error has occurred. Conda has prepared the above report.


# >>>>>>>>>>>>>>>>>>>>>> ERROR REPORT <<<<<<<<<<<<<<<<<<<<<<

    Traceback (most recent call last):
      File "/groups/itay_mayrose/galtoledano/miniconda3/lib/python3.11/site-packages/conda/exception_handler.py", line 16, in __call__
        return func(*args, **kwargs)
               ^^^^^^^^^^^^^^^^^^^^^
      File "/groups/itay_mayrose/galtoledano/miniconda3/lib/python3.11/site-packages/conda/cli/main.py", line 84, in main_subshell
        exit_code = do_call(args, p)
                    ^^^^^^^^^^^^^^^^
      File "/groups/itay_mayrose/galtoledano/miniconda3/lib/python3.11/site-packages/conda/cli/conda_argparse.py", line 126, in do_call
        return getattr(module, func_name)(args, parser)
               ^^^^^^^^^^^^^^^^^^^^^^^^^^^^^^^^^^^^^^^^
      File "/groups/itay_mayrose/galtoledano/miniconda3/lib/python3.11/site-packages/conda/cli/main_info.py", line 354, in execute
        print_envs_list(info_dict["envs"], not context.json)
      File "/groups/itay_mayrose/galtoledano/miniconda3/lib/python3.11/site-packages/conda/cli/common.py", line 242, in print_envs_list
        disp_env(prefix)
      File "/groups/itay_mayrose/galtoledano/miniconda3/lib/python3.11/site-packages/conda/cli/common.py", line 239, in disp_env
        print(fmt % (name, active, prefix))
    BrokenPipeError: [Errno 32] Broken pipe

`$ /groups/itay_mayrose/galtoledano/miniconda3/bin/conda info --envs`


An unexpected error has occurred. Conda has prepared the above report.

warning  libmamba Problem type not implemented SOLVER_RULE_STRICT_REPO_PRIORITY
warning  libmamba Problem type not implemented SOLVER_RULE_STRICT_REPO_PRIORITY
warning  libmamba Problem type not implemented SOLVER_RULE_STRICT_REPO_PRIORITY
warning  libmamba Problem type not implemented SOLVER_RULE_STRICT_REPO_PRIORITY
warning  libmamba Problem type not implemented SOLVER_RULE_STRICT_REPO_PRIORITY
warning  libmamba Invalid package cache, file '/groups/itay_mayrose/galtoledano/miniconda3/pkgs/python-3.10.12-hd12c33a_0_cpython/lib/python3.10/tokenize.py' has incorrect size

SafetyError: The package for python located at /groups/itay_mayrose/galtoledano/miniconda3/pkgs/python-3.10.12-hd12c33a_0_cpython
appears to be corrupted. The path 'lib/python3.10/tokenize.py'
has an incorrect size.
  reported size: 25921 bytes
  actual size: 25916 bytes


warning  libmamba Problem type not implemented SOLVER_RULE_STRICT_REPO_PRIORITY
warning  libmamba Problem type not implemented SOLVER_RULE_STRICT_REPO_PRIORITY
warning  libmamba Problem type not implemented SOLVER_RULE_STRICT_REPO_PRIORITY
warning  libmamba Problem type not implemented SOLVER_RULE_STRICT_REPO_PRIORITY

CondaEnvironmentError: cannot remove current environment. deactivate and run conda remove again


CondaValueError: prefix already exists: /groups/itay_mayrose/galtoledano/miniconda3/envs/snakemake-panoramic

